<?xml version="1.0"?>
<robot name = "vehicle">
    <!-- GAZEBO PLUGINS -->
    <gazebo>
        <plugin name = "differential_drive_controller"
                filename = "libgazebo_ros_diff_drive.so">
            <leftJoint>front_left_wheel_joint</leftJoint>
            <rightJoint>front_right_wheel_joint</rightJoint>
            <robotBaseFrame>base_link</robotBaseFrame>
            <wheelSeparation>0.09</wheelSeparation>
            <wheelDiameter>0.0984</wheelDiameter>
            <publishWheelJointState>true</publishWheelJointState>
        </plugin>
        <plugin name = "joint_state_publisher"
                filename = "libgazebo_ros_joint_state_publisher.so">
            <jointName>middle_back_caster_joint, middle_back_caster_wheel_joint</jointName>
        </plugin>
    </gazebo>

    <!-- CHASSIS -->
    <link name = "base_link">
        <visual>
            <geometry>
                <box size = ".135 0.09 0.05"/>
            </geometry>
            <material name = "plastic">
                <color rgba = "0.2 0.2 0.2 1"/>
            </material>
        </visual>
        <collision>
            <geometry>
                <box size = ".135 0.09 0.05"/>
            </geometry>
        </collision>
        <inertial>
            <mass value = "3.0"/>
            <inertia ixx = "0.015" iyy = "0.0375" izz = "0.000167"
                     ixy = "0"     ixz = "0"      iyz = "0"/>
        </inertial>
    </link>

    <!-- LEFT WHEEL -->
    <link name = "front_left_axle">
        <visual>
            <geometry>
                <cylinder length = "0.001" radius = "0.01"/>
            </geometry>
            <material name = "plastic">
                <color rgba = " 0.9 0.9 0.9 1"/>
            </material>
        </visual>
        <collision>
            <geometry>
                <cylinder length = "0.01" radius = "0.01"/>
            </geometry>
        </collision>
        <inertial>
            <mass value = "0.1"/>
            <inertia ixx = "5.1458e-5" iyy = "5.1458e-5" izz = "6.125e-5"
                     ixy = "0"         ixz = "0"         iyz = "0"/>
        </inertial>
    </link>

    <joint name = "front_left_axle_joint" type = "fixed">
        <axis xyz = "0 0 0"/>
        <parent link = "base_link"/>
        <child link = "front_left_axle"/>
        <origin rpy = "1.5707963268 0 0" xyz = "0.04 0.046 -0.01"/>
    </joint>

    <link name = "front_left_wheel">
        <visual>
            <geometry>
                <cylinder length="0.025" radius="0.0342"/>
            </geometry>
            <material name = "plastic">
                <color rgba = "0.9 0.9 0.9 1"/>
            </material>
        </visual>
        <collision>
            <geometry>
                <cylinder length="0.025" radius="0.0342"/>
            </geometry>
        </collision>
        <inertial>
            <mass value = "0.1"/>
            <inertia ixx = "5.1458e-5" iyy = "5.1458e-5" izz = "6.125e-5"
                     ixy = "0"         ixz = "0"         iyz = "0"/>
        </inertial>
    </link>

    <joint name = "front_left_wheel_joint" type = "continuous">
        <axis xyz = "0 0 -1"/>
        <parent link = "front_left_axle"/>
        <child link = "front_left_wheel"/>
        <origin rpy = "0 0 0" xyz = "0 0 -0.015"/>
    </joint>

    <!-- RIGHT WHEEL -->
    <link name = "front_right_axle">
        <visual>
            <geometry>
                <cylinder length = "0.001" radius = "0.01"/>
            </geometry>
            <material name = "plastic">
                <color rgba = " 0.9 0.9 0.9 1"/>
            </material>
        </visual>
        <collision>
            <geometry>
                <cylinder length = "0.01" radius = "0.01"/>
            </geometry>
        </collision>
        <inertial>
            <mass value = "0.1"/>
            <inertia ixx = "5.1458e-5" iyy = "5.1458e-5" izz = "6.125e-5"
                     ixy = "0"         ixz = "0"         iyz = "0"/>
        </inertial>
    </link>

    <joint name = "front_right_axle_joint" type = "fixed">
        <axis xyz = "0 0 0"/>
        <parent link = "base_link"/>
        <child link = "front_right_axle"/>
        <origin rpy = "-1.5707963268 0 0" xyz = "0.04 -0.046 -0.01"/>
    </joint>

    <link name = "front_right_wheel">
        <visual>
            <geometry>
                <cylinder length="0.025" radius="0.0342"/>
            </geometry>
            <material name = "plastic">
                <color rgba = "0.9 0.9 0.9 1"/>
            </material>
        </visual>
        <collision>
            <geometry>
                <cylinder length="0.025" radius="0.0342"/>
            </geometry>
        </collision>
        <inertial>
            <mass value = "0.1"/>
            <inertia ixx = "5.1458e-5" iyy = "5.1458e-5" izz = "6.125e-5"
                     ixy = "0"         ixz = "0"         iyz = "0"/>
        </inertial>
    </link>

    <joint name = "front_right_wheel_joint" type = "continuous">
        <axis xyz = "0 0 1"/>
        <parent link = "front_right_axle"/>
        <child link = "front_right_wheel"/>
        <origin rpy = "0 0 0" xyz = "0 0 -0.015"/>
    </joint>

    <!-- BACK CASTER -->
    <link name = "middle_back_caster">
        <visual>
            <geometry>
                <box size = "0.005 0.005 0.05"/>
            </geometry>
            <material name = "plastic"/>
                <color rgba = "0.9 0.9 0.9 1"/>
        </visual>
        <collision>
            <geometry>
                <box size = "0.005 0.005 0.05"/>
            </geometry>
        </collision>
        <inertial>
            <mass value = "0.1"/>
            <inertia ixx = "0.00083" iyy = "0.00083" izz = "0.000167"
                     ixy = "0"         ixz = "0"         iyz = "0"/>
        </inertial>
    </link>

    <joint name = "middle_back_caster_joint" type = "revolute">
        <axis xyz = "0 0 1"/>
        <limit effort="1000.0" lower="-1.5707963268" upper="1.5707963268" velocity="0.5"/>
        <parent link = "base_link"/>
        <child link = "middle_back_caster"/>
        <origin rpy = "0 0 0" xyz = "-0.05 -0.005 0"/>
    </joint>

    <link name = "middle_back_caster_wheel">
        <visual>
            <geometry>
                <sphere radius="0.0125"/>
            </geometry>
            <material name = "plastic">
                <color rgba = "0.9 0.9 0.9 1"/>
            </material>
        </visual>
        <collision>
            <geometry>
                <sphere radius="0.0125"/>
            </geometry>
            <surface>
                <friction>
					<ode>
						<mu>0.0</mu>
						<mu2>0.0</mu2>
						<fdir1> 0 0 0</fdir1>
						<slip1>1.0</slip1>
						<slip2>1.0</slip2>
					</ode>
				</friction>
            </surface>
        </collision>
        <inertial>
            <mass value = "0.1"/>
            <inertia ixx = "1e-6" iyy = "1e-6" izz = "1e-6"
                     ixy = "0"         ixz = "0"         iyz = "0"/>
        </inertial>
    </link>

    <joint name = "middle_back_caster_wheel_joint" type = "continuous">
        <axis xyz = "0 0 1"/>
        <parent link = "middle_back_caster"/>
        <child link = "middle_back_caster_wheel"/>
        <origin rpy = "-1.5707963268 0 0" xyz = "0 0 -0.03"/>
    </joint>

    <!-- CAMERA -->
    <link name = "front_camera_link">
        <visual>
            <geometry>
                <box size = "0.025 0.025 0.02"/>
            </geometry>
            <material name = "plastic">
                <color rgba = "0.9 0.9 0.9 1"/>
            </material>
        </visual>
        <collision>
            <geometry>
                <box size = "0.025 0.025 0.02"/>
            </geometry>
        </collision>
        <inertial>
            <mass value = "1e-5"/>
            <inertia ixx = "1e-6" iyy = "1e-6" izz = "1e-6"
                     ixy = "0"         ixz = "0"         iyz = "0"/>
        </inertial>
    </link>

    <joint name = "front_camera_joint" type = "fixed">
        <axis xyz = "0 1 0" />
        <origin xyz = "0.0675 0 0.03" rpy = "0 0 0" />
        <parent link = "base_link" />
        <child link = "front_camera_link" />
    </joint>

    <gazebo reference = "front_camera_link">
        <sensor type="camera" name="camera0">
            <update_rate>10.0</update_rate>
            <camera name="head">
                <horizontal_fov>2.7070057</horizontal_fov>
                <image>
                <width>3280</width>
                <height>2464</height>
                <format>R8G8B8</format>
                </image>
                <clip>
                <near>0.02</near>
                <far>300</far>
                </clip>
                <noise>
                <type>gaussian</type>
                <!-- Noise is sampled independently per pixel on each frame.
                    That pixel's noise value is added to each of its color
                    channels, which at that point lie in the range [0,1]. -->
                <mean>0.0</mean>
                <stddev>0.007</stddev>
                </noise>
            </camera>
            <plugin name="camera_controller" filename="libgazebo_ros_camera.so">
                <alwaysOn>true</alwaysOn>
                <updateRate>0.0</updateRate>
                <cameraName>prototype_vehicle/camera0</cameraName>
                <imageTopicName>image_raw</imageTopicName>
                <cameraInfoTopicName>camera_info</cameraInfoTopicName>
                <frameName>front_camera_link</frameName>
                <hackBaseline>0.07</hackBaseline>
                <distortionK1>0.0</distortionK1>
                <distortionK2>0.0</distortionK2>
                <distortionK3>0.0</distortionK3>
                <distortionT1>0.0</distortionT1>
                <distortionT2>0.0</distortionT2>
            </plugin>
        </sensor>
    </gazebo>

    <!-- ULTRASONIC SENSOR -->
    <link name = "ultrasonic_sensor_link">
        <visual>
            <geometry>
                <box size = "0.025 0.05 0.02"/>
            </geometry>
            <material name = "plastic">
                <color rgba = "0.9 0.9 0.9 1"/>
            </material>
        </visual>
        <collision>
            <geometry>
                <box size = "0.025 0.05 0.02"/>
            </geometry>
        </collision>
        <inertial>
            <mass value = "1e-5"/>
            <inertia ixx = "1e-6" iyy = "1e-6" izz = "1e-6"
                     ixy = "0"         ixz = "0"         iyz = "0"/>
        </inertial>
    </link>

    <joint name = "ultra_sonic_sensor_joint" type = "fixed">
        <axis xyz = "0 0 0" />
        <origin xyz = "0.0675 0 0" rpy = "0 0 0" />
        <parent link = "base_link" />
        <child link = "ultrasonic_sensor_link" />
    </joint>

    <gazebo reference="ultrasonic_sensor_link">        
        <sensor type="ray" name="ultrasonic0">
            <pose>0 0 0 0 0 0</pose>
            <visualize>true</visualize>
            <update_rate>10</update_rate>
            <ray>
                <scan>
                    <horizontal>
                    <samples>40</samples>
                    <resolution>1</resolution> 
                    <min_angle>-0.261799</min_angle>
                    <max_angle>0.261799</max_angle>
                    </horizontal>
                    <vertical>
                    <samples>10</samples>
                    <resolution>1</resolution> 
                    <min_angle>-0.0349066</min_angle>
                    <max_angle>0.0349066</max_angle> 
                    </vertical>
                </scan>
                <range>
                    <min>0.02</min>
                    <max>4</max>
                    <resolution>0.02</resolution>
                </range>
            </ray>
            <plugin filename="libgazebo_ros_range.so" name="gazebo_ros_range">
                <gaussianNoise>0.005</gaussianNoise>
                <alwaysOn>true</alwaysOn>
                <updateRate>50</updateRate>
                <topicName>sensor/ir_front</topicName>
                <frameName>ultrasonic_sensor_link</frameName>
                <radiation>INFRARED</radiation>
                <fov>0.2967</fov>
            </plugin>
        </sensor>  
   </gazebo>
</robot>